============================================================================ test session starts ============================================================================
platform linux -- Python 3.9.12, pytest-8.4.2, pluggy-1.6.0 -- /home/rts/anaconda3/envs/mutmut39/bin/python3.9
cachedir: .pytest_cache
metadata: {'Python': '3.9.12', 'Platform': 'Linux-5.4.0-150-generic-x86_64-with-glibc2.27', 'Packages': {'pytest': '8.4.2', 'pluggy': '1.6.0'}, 'Plugins': {'metadata': '3.1.1', 'html': '4.1.1', 'check': '2.5.3', 'json-report': '1.5.0'}}
rootdir: /home/rts/下载/Python_src/mutants
configfile: pytest.ini
plugins: metadata-3.1.1, html-4.1.1, check-2.5.3, json-report-1.5.0
collecting ... collected 0 items / 1 error

================================================================================== ERRORS ===================================================================================
_________________________________________________________________ ERROR collecting tests/test_add_values.py _________________________________________________________________
ImportError while importing test module '/home/rts/下载/Python_src/mutants/tests/test_add_values.py'.
Hint: make sure your test modules/packages have valid Python names.
Traceback:
../../anaconda3/envs/mutmut39/lib/python3.9/site-packages/_pytest/python.py:498: in importtestmodule
    mod = import_path(
../../anaconda3/envs/mutmut39/lib/python3.9/site-packages/_pytest/pathlib.py:587: in import_path
    importlib.import_module(module_name)
../../anaconda3/envs/mutmut39/lib/python3.9/importlib/__init__.py:127: in import_module
    return _bootstrap._gcd_import(name[level:], package, level)
<frozen importlib._bootstrap>:1030: in _gcd_import
    ???
<frozen importlib._bootstrap>:1007: in _find_and_load
    ???
<frozen importlib._bootstrap>:986: in _find_and_load_unlocked
    ???
<frozen importlib._bootstrap>:680: in _load_unlocked
    ???
../../anaconda3/envs/mutmut39/lib/python3.9/site-packages/_pytest/assertion/rewrite.py:186: in exec_module
    exec(co, module.__dict__)
mutants/tests/test_add_values.py:3: in <module>
    from mutants import runner
E   ModuleNotFoundError: No module named 'mutants'
============================================================================= warnings summary ==============================================================================
../../anaconda3/envs/mutmut39/lib/python3.9/site-packages/_pytest/config/__init__.py:1474
  /home/rts/anaconda3/envs/mutmut39/lib/python3.9/site-packages/_pytest/config/__init__.py:1474: PytestConfigWarning: Unknown config option: pytest -vv --tb
  
    self._warn_or_fail_if_strict(f"Unknown config option: {key}\n")

-- Docs: https://docs.pytest.org/en/stable/how-to/capture-warnings.html
-------------------------------------------------------------------------------- JSON report --------------------------------------------------------------------------------
report saved to: pytest_mutationen_report.json
========================================================================== short test summary info ==========================================================================
ERROR mutants/tests/test_add_values.py
!!!!!!!!!!!!!!!!!!!!!!!!!!!!!!!!!!!!!!!!!!!!!!!!!!!!!!!!!!!!!!!!!! Interrupted: 1 error during collection !!!!!!!!!!!!!!!!!!!!!!!!!!!!!!!!!!!!!!!!!!!!!!!!!!!!!!!!!!!!!!!!!!!
======================================================================== 1 warning, 1 error in 0.17s ========================================================================
